Workbook

Sheet Dashboard
A1: INDIA CPI INFLATION — INTERVIEW DASHBOARD
A4: CPI case study covering category contribution, inflation trends, COVID impact, food dynamics and imported-oil relationships.
A6: Q1 — Top Contribution | C6: Q2 — Highest Full-Year YoY | E6: Q3 — Food 12M Change | G6: Q4 — Headline Pre → Post | J6: Q5 — Strongest Correlation
A7: ='Q1 Contribution'!B21 -> Pan, Tobacco & Intoxicants | C7: ='Q2 Calculation'!B23 -> 2022 | E7: ="May-22 → May-23" -> May-22 → May-23 | G7: =TEXT('Q4 Calculation'!Q4,"0.00%")&" → "&TEXT('Q4 Calculation'!R4,"0.00%") -> 4.76% → 5.80% | J7: ='Q5 Calculation'!B73 -> Oils and fats
A8: ='Q1 Contribution'!D21 -> 0.10162387 | C8: ='Q2 Calculation'!D23 -> 0.066219355 | E8: ='Q3 Calculation'!B36 -> 0.030112316 | G8: ='Q4 Calculation'!S4 -> 0.010482467 | J8: ='Q5 Calculation'!B74 -> 0.40446503
A11: Q1 Analysis | C11: Q2 Calculation | E11: Q3 Calculation | G11: Q4 Calculation | I11: Q5 Calculation | K11: Project Guide
A13: Q1 — CPI Contribution | G13: Q2 — Annual Inflation Trend
M15: Q1 — CPI Basket
M16: The basket is broadly distributed across categories.
M17: Pan, Tobacco & Intoxicants has the
M18: highest calculated contribution, while Transport & Communication has the lowest..
M19: calculated contribution, while Transport & Communication has the lowest.
A31: Q3 — Food Inflation | G31: Q4 — COVID Impact
A38: Q2 — Inflation Trend | D38: Full-year YoY inflation peaked at 6.62% in 2022, reflecting global commodity shocks, food and energy pressures, supply constraints and pass-through into core prices.
A40: Q3 — Food | D40: Food prices remained volatile, with a 3.01% increase in the Food Index from May 2022 to May 2023. Spices showed the largest individual index increase.
A42: Q4 — COVID-19 | D42: Average headline inflation rose by about 1.05 percentage points after the March 2020 COVID reference point. Food and essential services rose, while health behaved differently.
A47: Q5 — Imported Oil vs CPI
A64: Q5 — Imported Oil | D64: I compared monthly changes in imported crude oil prices with inflation changes across CPI categories from 2021 to 2023.Oil prices showed major fluctuations, especially around 2022. Using Excel’s CORREL function, I checked which categories moved most closely with oil prices.Oils & Fats had the highest positive correlation at 0.404. This means Oils & Fats prices tended to move in the same direction as oil prices.However, the relationship was only moderate, not very strong.Fuel & Light also showed a relatively weak relationship.This shows that oil-price changes do not immediately or equally affect all CPI categories.Taxes, exchange rates and domestic pricing can delay or reduce the impact. Overall, oil prices influence inflation, but the impact is not immediate or one-to-one.

Sheet Project Guide
A1: India CPI Inflation Case Study — Project Guide
A4: Purpose | B4: Interview-ready analysis of India CPI inflation, category contribution, annual inflation, COVID impact, food inflation and imported crude-oil relationships.
A6: Questions Covered
A8: Q1 | B8: CPI contribution by broader categories — latest month May 2023; equal-weighted category construction.
A9: Q2 | B9: Annual Rural+Urban CPI YoY inflation from 2017; 2023 shown separately as Jan–May YTD.
A10: Q3 | B10: Food inflation over the 12 months ending May 2023, including MoM movement and biggest food-category change.
A11: Q4 | B11: COVID-19 impact using March 2020 as the reference milestone; pre/post 12-month comparison plus category focus.
A12: Q5 | B12: Imported Indian Basket crude-oil MoM changes for 2021–2023 and correlation with CPI-category MoM changes.
A15: Key Methodology / Interview Points
A17: Q1 | B17: AVERAGE for equal-weighted broader categories; contribution = category index ÷ sum of broader-category indices.
A18: Q2 | B18: Annual CPI = AVERAGEIFS of monthly General Index; YoY = current annual average ÷ previous annual average − 1.
A19: Q3 | B19: Food Index = AVERAGE of mapped food components; MoM = current index ÷ prior-month index − 1; absolute 12-month change by subtraction.
A20: Q4 | B20: Monthly YoY = current CPI ÷ same month previous year − 1; compare Apr-2019–Mar-2020 with Apr-2020–Mar-2021.
A21: Q5 | B21: MoM oil/CPI momentum followed by CORREL; ABS and RANK used to compare relationship strength. Correlation ≠ causation.
A24: Data Sources & Caveats
A26: • | B26: Primary CPI source: provided All-India CPI dataset; cleaned version retains 372 data rows and 30 columns.
A27: • | B27: Q5 oil source: Indian Basket crude-oil monthly price series; CPI correlation is limited to the overlapping CPI period Jan-2021 to May-2023 because the provided CPI dataset ends in May 2023.
A28: • | B28: Q2 and Q4 use linear interpolation only where required by the specific analysis and flag those observations; this does not alter the raw/clean source sheets.
A29: • | B29: Q1 uses equal weights across detailed categories because that is the case-study instruction, not the official CPI weighting system.
A30: • | B30: Q4 Essential Services is an analytical composite of Fuel & Light, Household Goods & Services and Transport & Communication; it is not an official CPI basket category.
A33: Interview Story — 60 Seconds
A34: I cleaned and standardized the CPI data, mapped detailed categories into broader analytical groups, and built five analyses. I first quantified how categories contribute to the CPI basket, then calculated annual inflation trends. I used March 2020 as a COVID milestone to compare pre- and post-onset inflation, and separately tested food inflation dynamics. Finally, I joined imported Indian Basket crude-oil prices with CPI data, calculated MoM movements and used CORREL to identify categories most associated with oil-price fluctuations. The key analytical point is that correlation indicates association, not causation, and monthly pass-through can be delayed or muted by taxes, administered prices, exchange rates and other supply shocks.

Sheet Raw Data
A1: Sector | B1: Year | C1: Month | D1: Cereals and products | E1: Meat and fish | F1: Egg | G1: Milk and products | H1: Oils and fats | I1: Fruits | J1: Vegetables | K1: Pulses and products | L1: Sugar and Confectionery | M1: Spices | N1: Non-alcoholic beverages | O1: Prepared meals, snacks, sweets etc. | P1: Food and beverages | Q1: Pan, tobacco and intoxicants | R1: Clothing | S1: Footwear | T1: Clothing and footwear | U1: Housing | V1: Fuel and light | W1: Household goods and services | X1: Health | Y1: Transport and communication | Z1: Recreation and amusement | AA1: Education | AB1: Personal care and effects | AC1: Miscellaneous | AD1: General index
A2: Rural | B2: 2013 | C2: January | D2: 107.5 | E2: 106.3 | F2: 108.1 | G2: 104.9 | H2: 106.1 | I2: 103.9 | J2: 101.9 | K2: 106.1 | L2: 106.8 | M2: 103.1 | N2: 104.8 | O2: 106.7 | P2: 105.5 | Q2: 105.1 | R2: 106.5 | S2: 105.8 | T2: 106.4 | V2: 105.5 | W2: 104.8 | X2: 104 | Y2: 103.3 | Z2: 103.4 | AA2: 103.8 | AB2: 104.7 | AC2: 104 | AD2: 105.1 | AE2: ← Dashboard
A3: Urban | B3: 2013 | C3: January | D3: 110.5 | E3: 109.1 | F3: 113 | G3: 103.6 | H3: 103.4 | I3: 102.3 | J3: 102.9 | K3: 105.8 | L3: 105.1 | M3: 101.8 | N3: 105.1 | O3: 107.9 | P3: 105.9 | Q3: 105.2 | R3: 105.9 | S3: 105 | T3: 105.8 | U3: 100.3 | V3: 105.4 | W3: 104.8 | X3: 104.1 | Y3: 103.2 | Z3: 102.9 | AA3: 103.5 | AB3: 104.3 | AC3: 103.7 | AD3: 104
A4: Rural+Urban | B4: 2013 | C4: January | D4: 108.4 | E4: 107.3 | F4: 110 | G4: 104.4 | H4: 105.1 | I4: 103.2 | J4: 102.2 | K4: 106 | L4: 106.2 | M4: 102.7 | N4: 104.9 | O4: 107.3 | P4: 105.6 | Q4: 105.1 | R4: 106.3 | S4: 105.5 | T4: 106.2 | U4: 100.3 | V4: 105.5 | W4: 104.8 | X4: 104 | Y4: 103.2 | Z4: 103.1 | AA4: 103.6 | AB4: 104.5 | AC4: 103.9 | AD4: 104.6
A5: Rural | B5: 2013 | C5: February | D5: 109.2 | E5: 108.7 | F5: 110.2 | G5: 105.4 | H5: 106.7 | I5: 104 | J5: 102.4 | K5: 105.9 | L5: 105.7 | M5: 103.1 | N5: 105.1 | O5: 107.7 | P5: 106.3 | Q5: 105.6 | R5: 107.1 | S5: 106.3 | T5: 107 | V5: 106.2 | W5: 105.2 | X5: 104.4 | Y5: 103.9 | Z5: 104 | AA5: 104.1 | AB5: 104.6 | AC5: 104.4 | AD5: 105.8
A6: Urban | B6: 2013 | C6: February | D6: 112.9 | E6: 112.9 | F6: 116.9 | G6: 104 | H6: 103.5 | I6: 103.1 | J6: 104.9 | K6: 104.1 | L6: 103.8 | M6: 102.3 | N6: 106 | O6: 109 | P6: 107.2 | Q6: 106 | R6: 106.6 | S6: 105.5 | T6: 106.4 | U6: 100.4 | V6: 105.7 | W6: 105.2 | X6: 104.7 | Y6: 104.4 | Z6: 103.3 | AA6: 103.7 | AB6: 104.3 | AC6: 104.3 | AD6: 104.7
A7: Rural+Urban | B7: 2013 | C7: February | D7: 110.4 | E7: 110.2 | F7: 112.8 | G7: 104.9 | H7: 105.5 | I7: 103.6 | J7: 103.2 | K7: 105.3 | L7: 105.1 | M7: 102.8 | N7: 105.5 | O7: 108.3 | P7: 106.6 | Q7: 105.7 | R7: 106.9 | S7: 106 | T7: 106.8 | U7: 100.4 | V7: 106 | W7: 105.2 | X7: 104.5 | Y7: 104.2 | Z7: 103.6 | AA7: 103.9 | AB7: 104.5 | AC7: 104.4 | AD7: 105.3
A8: Rural | B8: 2013 | C8: March | D8: 110.2 | E8: 108.8 | F8: 109.9 | G8: 105.6 | H8: 106.2 | I8: 105.7 | J8: 101.4 | K8: 105.7 | L8: 105 | M8: 103.3 | N8: 105.6 | O8: 108.2 | P8: 106.6 | Q8: 106.5 | R8: 107.6 | S8: 106.8 | T8: 107.5 | V8: 106.1 | W8: 105.6 | X8: 104.7 | Y8: 104.6 | Z8: 104 | AA8: 104.3 | AB8: 104.3 | AC8: 104.6 | AD8: 106
A9: Urban | B9: 2013 | C9: March | D9: 113.9 | E9: 111.4 | F9: 113.2 | G9: 104.3 | H9: 102.7 | I9: 104.9 | J9: 103.8 | K9: 103.5 | L9: 102.6 | M9: 102.4 | N9: 107 | O9: 109.8 | P9: 107.3 | Q9: 106.8 | R9: 107.2 | S9: 106 | T9: 107 | U9: 100.4 | V9: 106 | W9: 105.7 | X9: 105.2 | Y9: 105.5 | Z9: 103.5 | AA9: 103.8 | AB9: 104.2 | AC9: 104.9 | AD9: 105
A10: Rural+Urban | B10: 2013 | C10: March | D10: 111.4 | E10: 109.7 | F10: 111.2 | G10: 105.1 | H10: 104.9 | I10: 105.3 | J10: 102.2 | K10: 105 | L10: 104.2 | M10: 103 | N10: 106.2 | O10: 108.9 | P10: 106.9 | Q10: 106.6 | R10: 107.4 | S10: 106.5 | T10: 107.3 | U10: 100.4 | V10: 106.1 | W10: 105.6 | X10: 104.9 | Y10: 105.1 | Z10: 103.7 | AA10: 104 | AB10: 104.3 | AC10: 104.7 | AD10: 105.5
A11: Rural | B11: 2013 | C11: April | D11: 110.2 | E11: 109.5 | F11: 106.9 | G11: 106.3 | H11: 105.7 | I11: 108.3 | J11: 103.4 | K11: 105.7 | L11: 104.2 | M11: 103.2 | N11: 106.5 | O11: 108.8 | P11: 107.1 | Q11: 107.1 | R11: 108.1 | S11: 107.4 | T11: 108 | V11: 106.5 | W11: 106.1 | X11: 105.1 | Y11: 104.4 | Z11: 104.5 | AA11: 104.8 | AB11: 102.7 | AC11: 104.6 | AD11: 106.4
A12: Urban | B12: 2013 | C12: April | D12: 114.6 | E12: 113.4 | F12: 106 | G12: 104.7 | H12: 102.1 | I12: 109.5 | J12: 109.7 | K12: 104.6 | L12: 102 | M12: 103.5 | N12: 108.2 | O12: 110.6 | P12: 108.8 | Q12: 108.5 | R12: 107.9 | S12: 106.4 | T12: 107.7 | U12: 100.5 | V12: 106.4 | W12: 106.5 | X12: 105.7 | Y12: 105 | Z12: 104 | AA12: 105.2 | AB12: 103.2 | AC12: 105.1 | AD12: 105.7
A13: Rural+Urban | B13: 2013 | C13: April | D13: 111.6 | E13: 110.9 | F13: 106.6 | G13: 105.7 | H13: 104.4 | I13: 108.9 | J13: 105.5 | K13: 105.3 | L13: 103.5 | M13: 103.3 | N13: 107.2 | O13: 109.6 | P13: 107.7 | Q13: 107.5 | R13: 108 | S13: 107 | T13: 107.9 | U13: 100.5 | V13: 106.5 | W13: 106.3 | X13: 105.3 | Y13: 104.7 | Z13: 104.2 | AA13: 105 | AB13: 102.9 | AC13: 104.8 | AD13: 106.1
A14: Rural | B14: 2013 | C14: May | D14: 110.9 | E14: 109.8 | F14: 105.9 | G14: 107.5 | H14: 105.3 | I14: 108.1 | J14: 107.3 | K14: 106.1 | L14: 103.7 | M14: 104 | N14: 107.4 | O14: 109.9 | P14: 108.1 | Q14: 108.1 | R14: 108.8 | S14: 107.9 | T14: 108.6 | V14: 107.5 | W14: 106.8 | X14: 105.7 | Y14: 104.1 | Z14: 105 | AA14: 105.5 | AB14: 102.1 | AC14: 104.8 | AD14: 107.2
A15: Urban | B15: 2013 | C15: May | D15: 115.4 | E15: 114.2 | F15: 102.7 | G15: 105.5 | H15: 101.5 | I15: 110.6 | J15: 123.7 | K15: 105.2 | L15: 101.9 | M15: 105 | N15: 109.1 | O15: 111.3 | P15: 111.1 | Q15: 109.8 | R15: 108.5 | S15: 106.7 | T15: 108.3 | U15: 100.5 | V15: 107.2 | W15: 107.1 | X15: 106.2 | Y15: 103.9 | Z15: 104.6 | AA15: 105.7 | AB15: 102.6 | AC15: 104.9 | AD15: 106.6
A16: Rural+Urban | B16: 2013 | C16: May | D16: 112.3 | E16: 111.3 | F16: 104.7 | G16: 106.8 | H16: 103.9 | I16: 109.3 | J16: 112.9 | K16: 105.8 | L16: 103.1 | M16: 104.3 | N16: 108.1 | O16: 110.5 | P16: 109.2 | Q16: 108.6 | R16: 108.7 | S16: 107.4 | T16: 108.5 | U16: 100.5 | V16: 107.4 | W16: 106.9 | X16: 105.9 | Y16: 104 | Z16: 104.8 | AA16: 105.6 | AB16: 102.3 | AC16: 104.8 | AD16: 106.9
A17: Rural | B17: 2013 | C17: June | D17: 112.3 | E17: 112.1 | F17: 108.1 | G17: 108.3 | H17: 105.9 | I17: 109.2 | J17: 118 | K17: 106.8 | L17: 104.1 | M17: 105.4 | N17: 108.2 | O17: 111 | P17: 110.6 | Q17: 109 | R17: 109.7 | S17: 108.8 | T17: 109.5 | V17: 108.5 | W17: 107.5 | X17: 106.3 | Y17: 105 | Z17: 105.6 | AA17: 106.5 | AB17: 102.5 | AC17: 105.5 | AD17: 108.9
A18: Urban | B18: 2013 | C18: June | D18: 117 | E18: 120.1 | F18: 112.5 | G18: 107.3 | H18: 101.3 | I18: 112.4 | J18: 143.6 | K18: 105.4 | L18: 101.4 | M18: 106.4 | N18: 110 | O18: 112.2 | P18: 115 | Q18: 110.9 | R18: 109.2 | S18: 107.2 | T18: 108.9 | U18: 106.6 | V18: 108 | W18: 107.7 | X18: 106.5 | Y18: 105.2 | Z18: 105.2 | AA18: 108.1 | AB18: 103.3 | AC18: 106.1 | AD18: 109.7
A19: Rural+Urban | B19: 2013 | C19: June | D19: 113.8 | E19: 114.9 | F19: 109.8 | G19: 107.9 | H19: 104.2 | I19: 110.7 | J19: 126.7 | K19: 106.3 | L19: 103.2 | M19: 105.7 | N19: 109 | O19: 111.6 | P19: 112.2 | Q19: 109.5 | R19: 109.5 | S19: 108.1 | T19: 109.3 | U19: 106.6 | V19: 108.3 | W19: 107.6 | X19: 106.4 | Y19: 105.1 | Z19: 105.4 | AA19: 107.4 | AB19: 102.8 | AC19: 105.8 | AD19: 109.3
A20: Rural | B20: 2013 | C20: July | D20: 113.4 | E20: 114.9 | F20: 110.5 | G20: 109.3 | H20: 106.2 | I20: 110.3 | J20: 129.2 | K20: 107.1 | L20: 104.3 | M20: 106.4 | N20: 109.1 | O20: 112.1 | P20: 113.1 | Q20: 109.8 | R20: 110.5 | S20: 109.5 | T20: 110.3 | V20: 109.5 | W20: 108.3 | X20: 106.9 | Y20: 106.8 | Z20: 106.4 | AA20: 107.8 | AB20: 102.5 | AC20: 106.5 | AD20: 110.7
A21: Urban | B21: 2013 | C21: July | D21: 117.8 | E21: 119.2 | F21: 114 | G21: 108.3 | H21: 101.1 | I21: 113.2 | J21: 160.9 | K21: 105.1 | L21: 101.3 | M21: 107.5 | N21: 110.4 | O21: 113.1 | P21: 117.5 | Q21: 111.7 | R21: 109.8 | S21: 107.8 | T21: 109.5 | U21: 107.7 | V21: 108.6 | W21: 108.1 | X21: 107.1 | Y21: 107.3 | Z21: 105.9 | AA21: 110.1 | AB21: 103.2 | AC21: 107.3 | AD21: 111.4
A22: Rural+Urban | B22: 2013 | C22: July | D22: 114.8 | E22: 116.4 | F22: 111.9 | G22: 108.9 | H22: 104.3 | I22: 111.7 | J22: 140 | K22: 106.4 | L22: 103.3 | M22: 106.8 | N22: 109.6 | O22: 112.6 | P22: 114.7 | Q22: 110.3 | R22: 110.2 | S22: 108.8 | T22: 110 | U22: 107.7 | V22: 109.2 | W22: 108.2 | X22: 107 | Y22: 107.1 | Z22: 106.1 | AA22: 109.1 | AB22: 102.8 | AC22: 106.9 | AD22: 111
A23: Rural | B23: 2013 | C23: August | D23: 114.3 | E23: 115.4 | F23: 111.1 | G23: 110 | H23: 106.4 | I23: 110.8 | J23: 138.9 | K23: 107.4 | L23: 104.1 | M23: 106.9 | N23: 109.7 | O23: 112.6 | P23: 114.9 | Q23: 110.7 | R23: 111.3 | S23: 110.2 | T23: 111.1 | V23: 109.9 | W23: 108.7 | X23: 107.5 | Y23: 107.8 | Z23: 106.8 | AA23: 108.7 | AB23: 105 | AC23: 107.5 | AD23: 112.1
A24: Urban | B24: 2013 | C24: August | D24: 118.3 | E24: 120.4 | F24: 112.7 | G24: 108.9 | H24: 101.1 | I24: 108.7 | J24: 177 | K24: 104.7 | L24: 101 | M24: 108.5 | N24: 110.9 | O24: 114.3 | P24: 119.6 | Q24: 112.4 | R24: 110.6 | S24: 108.3 | T24: 110.2 | U24: 108.9 | V24: 109.3 | W24: 108.7 | X24: 107.6 | Y24: 108.1 | Z24: 106.5 | AA24: 110.8 | AB24: 106 | AC24: 108.3 | AD24: 112.7
A25: Rural+Urban | B25: 2013 | C25: August | D25: 115.6 | E25: 117.2 | F25: 111.7 | G25: 109.6 | H25: 104.5 | I25: 109.8 | J25: 151.8 | K25: 106.5 | L25: 103.1 | M25: 107.4 | N25: 110.2 | O25: 113.4 | P25: 116.6 | Q25: 111.2 | R25: 111 | S25: 109.4 | T25: 110.7 | U25: 108.9 | V25: 109.7 | W25: 108.7 | X25: 107.5 | Y25: 108 | Z25: 106.6 | AA25: 109.9 | AB25: 105.4 | AC25: 107.9 | AD25: 112.4
A26: Rural | B26: 2013 | C26: September | D26: 115.4 | E26: 115.7 | F26: 111.7 | G26: 111 | H26: 107.4 | I26: 110.9 | J26: 154 | K26: 108.1 | L26: 104.2 | M26: 107.9 | N26: 110.4 | O26: 114 | P26: 117.8 | Q26: 111.7 | R26: 112.7 | S26: 111.4 | T26: 112.5 | V26: 111.1 | W26: 109.6 | X26: 108.3 | Y26: 109.3 | Z26: 107.7 | AA26: 109.8 | AB26: 106.7 | AC26: 108.7 | AD26: 114.2
A27: Urban | B27: 2013 | C27: September | D27: 118.6 | E27: 119.1 | F27: 113.2 | G27: 109.6 | H27: 101.7 | I27: 103.2 | J27: 174.3 | K27: 105.1 | L27: 100.8 | M27: 109.1 | N27: 111.1 | O27: 115.4 | P27: 119.2 | Q27: 112.9 | R27: 111.4 | S27: 109 | T27: 111.1 | U27: 109.7 | V27: 109.5 | W27: 109.6 | X27: 107.9 | Y27: 110.4 | Z27: 107.4 | AA27: 111.2 | AB27: 106.9 | AC27: 109.4 | AD27: 113.2
A28: Rural+Urban | B28: 2013 | C28: September | D28: 116.4 | E28: 116.9 | F28: 112.3 | G28: 110.5 | H28: 105.3 | I28: 107.3 | J28: 160.9 | K28: 107.1 | L28: 103.1 | M28: 108.3 | N28: 110.7 | O28: 114.6 | P28: 118.3 | Q28: 112 | R28: 112.2 | S28: 110.4 | T28: 111.9 | U28: 109.7 | V28: 110.5 | W28: 109.6 | X28: 108.1 | Y28: 109.9 | Z28: 107.5 | AA28: 110.6 | AB28: 106.8 | AC28: 109 | AD28: 113.7
A29: Rural | B29: 2013 | C29: October | D29: 116.3 | E29: 115.4 | F29: 112.6 | G29: 111.7 | H29: 107.7 | I29: 113.2 | J29: 164.9 | K29: 108.3 | L29: 103.9 | M29: 108.2 | N29: 111.1 | O29: 114.9 | P29: 119.8 | Q29: 112.2 | R29: 113.6 | S29: 112.3 | T29: 113.4 | V29: 111.6 | W29: 110.4 | X29: 108.9 | Y29: 109.3 | Z29: 108.3 | AA29: 110.2 | AB29: 107.5 | AC29: 109.1 | AD29: 115.5
A30: Urban | B30: 2013 | C30: October | D30: 118.9 | E30: 118.1 | F30: 114.5 | G30: 110.4 | H30: 102.3 | I30: 106.2 | J30: 183.5 | K30: 105.3 | L30: 100.2 | M30: 109.6 | N30: 111.4 | O30: 116 | P30: 120.8 | Q30: 113.5 | R30: 112.5 | S30: 109.7 | T30: 112 | U30: 110.5 | V30: 109.7 | W30: 110.2 | X30: 108.2 | Y30: 109.7 | Z30: 108 | AA30: 111.3 | AB30: 107.3 | AC30: 109.4 | AD30: 114
A31: Rural+Urban | B31: 2013 | C31: October | D31: 117.1 | E31: 116.3 | F31: 113.3 | G31: 111.2 | H31: 105.7 | I31: 109.9 | J31: 171.2 | K31: 107.3 | L31: 102.7 | M31: 108.7 | N31: 111.2 | O31: 115.4 | P31: 120.2 | Q31: 112.5 | R31: 113.2 | S31: 111.2 | T31: 112.8 | U31: 110.5 | V31: 110.9 | W31: 110.3 | X31: 108.6 | Y31: 109.5 | Z31: 108.1 | AA31: 110.8 | AB31: 107.4 | AC31: 109.2 | AD31: 114.8
A32: Rural | B32: 2013 | C32: November | D32: 117.3 | E32: 114.9 | F32: 116.2 | G32: 112.8 | H32: 108.9 | I32: 116.6 | J32: 178.1 | K32: 109.1 | L32: 103.6 | M32: 109 | N32: 111.8 | O32: 116 | P32: 122.5 | Q32: 112.8 | R32: 114.6 | S32: 113.1 | T32: 114.4 | V32: 112.6 | W32: 111.3 | X32: 109.7 | Y32: 109.6 | Z32: 108.7 | AA32: 111 | AB32: 108.2 | AC32: 109.8 | AD32: 117.4
A33: Urban | B33: 2013 | C33: November | D33: 119.8 | E33: 116.3 | F33: 122.6 | G33: 112 | H33: 103.2 | I33: 110 | J33: 192.8 | K33: 106.3 | L33: 99.5 | M33: 110.3 | N33: 111.8 | O33: 117.1 | P33: 122.9 | Q33: 114.1 | R33: 113.5 | S33: 110.3 | T33: 113 | U33: 111.1 | V33: 110 | W33: 110.9 | X33: 108.6 | Y33: 109.5 | Z33: 108.5 | AA33: 111.3 | AB33: 107.9 | AC33: 109.6 | AD33: 115
A34: Rural+Urban | B34: 2013 | C34: November | D34: 118.1 | E34: 115.4 | F34: 118.7 | G34: 112.5 | H34: 106.8 | I34: 113.5 | J34: 183.1 | K34: 108.2 | L34: 102.2 | M34: 109.4 | N34: 111.8 | O34: 116.5 | P34: 122.6 | Q34: 113.1 | R34: 114.2 | S34: 111.9 | T34: 113.8 | U34: 111.1 | V34: 111.6 | W34: 111.1 | X34: 109.3 | Y34: 109.5 | Z34: 108.6 | AA34: 111.2 | AB34: 108.1 | AC34: 109.7 | AD34: 116.3
A35: Rural | B35: 2013 | C35: December | D35: 118.4 | E35: 115.9 | F35: 120.4 | G35: 113.8 | H35: 109.5 | I35: 115.5 | J35: 145.7 | K35: 109.5 | L35: 102.9 | M35: 109.8 | N35: 112.1 | O35: 116.8 | P35: 118.7 | Q35: 113.6 | R35: 115.8 | S35: 114 | T35: 115.5 | V35: 112.8 | W35: 112.1 | X35: 110.1 | Y35: 109.9 | Z35: 109.2 | AA35: 111.6 | AB35: 108.1 | AC35: 110.1 | AD35: 115.5
A36: Urban | B36: 2013 | C36: December | D36: 120.5 | E36: 118.1 | F36: 128.5 | G36: 112.8 | H36: 103.4 | I36: 110.7 | J36: 144.8 | K36: 107.1 | L36: 98.6 | M36: 111.9 | N36: 112.1 | O36: 118.1 | P36: 117.8 | Q36: 115 | R36: 114.2 | S36: 110.9 | T36: 113.7 | U36: 110.7 | V36: 110.4 | W36: 111.3 | X36: 109 | Y36: 109.7 | Z36: 108.9 | AA36: 111.4 | AB36: 107.7 | AC36: 109.8 | AD36: 113.3
A37: Rural+Urban | B37: 2013 | C37: December | D37: 119.1 | E37: 116.7 | F37: 123.5 | G37: 113.4 | H37: 107.3 | I37: 113.3 | J37: 145.4 | K37: 108.7 | L37: 101.5 | M37: 110.5 | N37: 112.1 | O37: 117.4 | P37: 118.4 | Q37: 114 | R37: 115.2 | S37: 112.7 | T37: 114.8 | U37: 110.7 | V37: 111.9 | W37: 111.7 | X37: 109.7 | Y37: 109.8 | Z37: 109 | AA37: 111.5 | AB37: 107.9 | AC37: 110 | AD37: 114.5
A38: Rural | B38: 2014 | C38: January | D38: 118.9 | E38: 117.1 | F38: 120.5 | G38: 114.4 | H38: 109 | I38: 115.5 | J38: 123.9 | K38: 109.6 | L38: 101.8 | M38: 110.2 | N38: 112.4 | O38: 117.3 | P38: 116 | Q38: 114 | R38: 116.5 | S38: 114.5 | T38: 116.2 | V38: 113 | W38: 112.6 | X38: 110.6 | Y38: 110.5 | Z38: 109.6 | AA38: 111.8 | AB38: 108.3 | AC38: 110.6 | AD38: 114.2
A39: Urban | B39: 2014 | C39: January | D39: 121.2 | E39: 122 | F39: 129.9 | G39: 113.6 | H39: 102.9 | I39: 112.1 | J39: 118.9 | K39: 107.5 | L39: 96.9 | M39: 112.7 | N39: 112.1 | O39: 119 | P39: 115.5 | Q39: 115.7 | R39: 114.8 | S39: 111.3 | T39: 114.3 | U39: 111.6 | V39: 111 | W39: 111.9 | X39: 109.7 | Y39: 110.8 | Z39: 109.8 | AA39: 111.5 | AB39: 108 | AC39: 110.5 | AD39: 112.9
A40: Rural+Urban | B40: 2014 | C40: January | D40: 119.6 | E40: 118.8 | F40: 124.1 | G40: 114.1 | H40: 106.8 | I40: 113.9 | J40: 122.2 | K40: 108.9 | L40: 100.2 | M40: 111 | N40: 112.3 | O40: 118.1 | P40: 115.8 | Q40: 114.5 | R40: 115.8 | S40: 113.2 | T40: 115.4 | U40: 111.6 | V40: 112.2 | W40: 112.3 | X40: 110.3 | Y40: 110.7 | Z40: 109.7 | AA40: 111.6 | AB40: 108.2 | AC40: 110.6 | AD40: 113.6
...

Sheet Clean Data
A1: Sector | B1: Year | C1: Month | D1: Cereals and products | E1: Meat and fish | F1: Egg | G1: Milk and products | H1: Oils and fats | I1: Fruits | J1: Vegetables | K1: Pulses and products | L1: Sugar and Confectionery | M1: Spices | N1: Non-alcoholic beverages | O1: Prepared meals, snacks, sweets etc. | P1: Food and beverages | Q1: Pan, tobacco and intoxicants | R1: Clothing | S1: Footwear | T1: Clothing and footwear | U1: Housing | V1: Fuel and light | W1: Household goods and services | X1: Health | Y1: Transport and communication | Z1: Recreation and amusement | AA1: Education | AB1: Personal care and effects | AC1: Miscellaneous | AD1: General index
A2: Rural | B2: 2013 | C2: January | D2: 107.5 | E2: 106.3 | F2: 108.1 | G2: 104.9 | H2: 106.1 | I2: 103.9 | J2: 101.9 | K2: 106.1 | L2: 106.8 | M2: 103.1 | N2: 104.8 | O2: 106.7 | P2: 105.5 | Q2: 105.1 | R2: 106.5 | S2: 105.8 | T2: 106.4 | V2: 105.5 | W2: 104.8 | X2: 104 | Y2: 103.3 | Z2: 103.4 | AA2: 103.8 | AB2: 104.7 | AC2: 104 | AD2: 105.1 | AE2: ← Dashboard
A3: Urban | B3: 2013 | C3: January | D3: 110.5 | E3: 109.1 | F3: 113 | G3: 103.6 | H3: 103.4 | I3: 102.3 | J3: 102.9 | K3: 105.8 | L3: 105.1 | M3: 101.8 | N3: 105.1 | O3: 107.9 | P3: 105.9 | Q3: 105.2 | R3: 105.9 | S3: 105 | T3: 105.8 | U3: 100.3 | V3: 105.4 | W3: 104.8 | X3: 104.1 | Y3: 103.2 | Z3: 102.9 | AA3: 103.5 | AB3: 104.3 | AC3: 103.7 | AD3: 104
A4: Rural+Urban | B4: 2013 | C4: January | D4: 108.4 | E4: 107.3 | F4: 110 | G4: 104.4 | H4: 105.1 | I4: 103.2 | J4: 102.2 | K4: 106 | L4: 106.2 | M4: 102.7 | N4: 104.9 | O4: 107.3 | P4: 105.6 | Q4: 105.1 | R4: 106.3 | S4: 105.5 | T4: 106.2 | U4: 100.3 | V4: 105.5 | W4: 104.8 | X4: 104 | Y4: 103.2 | Z4: 103.1 | AA4: 103.6 | AB4: 104.5 | AC4: 103.9 | AD4: 104.6
A5: Rural | B5: 2013 | C5: February | D5: 109.2 | E5: 108.7 | F5: 110.2 | G5: 105.4 | H5: 106.7 | I5: 104 | J5: 102.4 | K5: 105.9 | L5: 105.7 | M5: 103.1 | N5: 105.1 | O5: 107.7 | P5: 106.3 | Q5: 105.6 | R5: 107.1 | S5: 106.3 | T5: 107 | V5: 106.2 | W5: 105.2 | X5: 104.4 | Y5: 103.9 | Z5: 104 | AA5: 104.1 | AB5: 104.6 | AC5: 104.4 | AD5: 105.8
A6: Urban | B6: 2013 | C6: February | D6: 112.9 | E6: 112.9 | F6: 116.9 | G6: 104 | H6: 103.5 | I6: 103.1 | J6: 104.9 | K6: 104.1 | L6: 103.8 | M6: 102.3 | N6: 106 | O6: 109 | P6: 107.2 | Q6: 106 | R6: 106.6 | S6: 105.5 | T6: 106.4 | U6: 100.4 | V6: 105.7 | W6: 105.2 | X6: 104.7 | Y6: 104.4 | Z6: 103.3 | AA6: 103.7 | AB6: 104.3 | AC6: 104.3 | AD6: 104.7
A7: Rural+Urban | B7: 2013 | C7: February | D7: 110.4 | E7: 110.2 | F7: 112.8 | G7: 104.9 | H7: 105.5 | I7: 103.6 | J7: 103.2 | K7: 105.3 | L7: 105.1 | M7: 102.8 | N7: 105.5 | O7: 108.3 | P7: 106.6 | Q7: 105.7 | R7: 106.9 | S7: 106 | T7: 106.8 | U7: 100.4 | V7: 106 | W7: 105.2 | X7: 104.5 | Y7: 104.2 | Z7: 103.6 | AA7: 103.9 | AB7: 104.5 | AC7: 104.4 | AD7: 105.3
A8: Rural | B8: 2013 | C8: March | D8: 110.2 | E8: 108.8 | F8: 109.9 | G8: 105.6 | H8: 106.2 | I8: 105.7 | J8: 101.4 | K8: 105.7 | L8: 105 | M8: 103.3 | N8: 105.6 | O8: 108.2 | P8: 106.6 | Q8: 106.5 | R8: 107.6 | S8: 106.8 | T8: 107.5 | V8: 106.1 | W8: 105.6 | X8: 104.7 | Y8: 104.6 | Z8: 104 | AA8: 104.3 | AB8: 104.3 | AC8: 104.6 | AD8: 106
A9: Urban | B9: 2013 | C9: March | D9: 113.9 | E9: 111.4 | F9: 113.2 | G9: 104.3 | H9: 102.7 | I9: 104.9 | J9: 103.8 | K9: 103.5 | L9: 102.6 | M9: 102.4 | N9: 107 | O9: 109.8 | P9: 107.3 | Q9: 106.8 | R9: 107.2 | S9: 106 | T9: 107 | U9: 100.4 | V9: 106 | W9: 105.7 | X9: 105.2 | Y9: 105.5 | Z9: 103.5 | AA9: 103.8 | AB9: 104.2 | AC9: 104.9 | AD9: 105
A10: Rural+Urban | B10: 2013 | C10: March | D10: 111.4 | E10: 109.7 | F10: 111.2 | G10: 105.1 | H10: 104.9 | I10: 105.3 | J10: 102.2 | K10: 105 | L10: 104.2 | M10: 103 | N10: 106.2 | O10: 108.9 | P10: 106.9 | Q10: 106.6 | R10: 107.4 | S10: 106.5 | T10: 107.3 | U10: 100.4 | V10: 106.1 | W10: 105.6 | X10: 104.9 | Y10: 105.1 | Z10: 103.7 | AA10: 104 | AB10: 104.3 | AC10: 104.7 | AD10: 105.5
A11: Rural | B11: 2013 | C11: April | D11: 110.2 | E11: 109.5 | F11: 106.9 | G11: 106.3 | H11: 105.7 | I11: 108.3 | J11: 103.4 | K11: 105.7 | L11: 104.2 | M11: 103.2 | N11: 106.5 | O11: 108.8 | P11: 107.1 | Q11: 107.1 | R11: 108.1 | S11: 107.4 | T11: 108 | V11: 106.5 | W11: 106.1 | X11: 105.1 | Y11: 104.4 | Z11: 104.5 | AA11: 104.8 | AB11: 102.7 | AC11: 104.6 | AD11: 106.4
A12: Urban | B12: 2013 | C12: April | D12: 114.6 | E12: 113.4 | F12: 106 | G12: 104.7 | H12: 102.1 | I12: 109.5 | J12: 109.7 | K12: 104.6 | L12: 102 | M12: 103.5 | N12: 108.2 | O12: 110.6 | P12: 108.8 | Q12: 108.5 | R12: 107.9 | S12: 106.4 | T12: 107.7 | U12: 100.5 | V12: 106.4 | W12: 106.5 | X12: 105.7 | Y12: 105 | Z12: 104 | AA12: 105.2 | AB12: 103.2 | AC12: 105.1 | AD12: 105.7
A13: Rural+Urban | B13: 2013 | C13: April | D13: 111.6 | E13: 110.9 | F13: 106.6 | G13: 105.7 | H13: 104.4 | I13: 108.9 | J13: 105.5 | K13: 105.3 | L13: 103.5 | M13: 103.3 | N13: 107.2 | O13: 109.6 | P13: 107.7 | Q13: 107.5 | R13: 108 | S13: 107 | T13: 107.9 | U13: 100.5 | V13: 106.5 | W13: 106.3 | X13: 105.3 | Y13: 104.7 | Z13: 104.2 | AA13: 105 | AB13: 102.9 | AC13: 104.8 | AD13: 106.1
A14: Rural | B14: 2013 | C14: May | D14: 110.9 | E14: 109.8 | F14: 105.9 | G14: 107.5 | H14: 105.3 | I14: 108.1 | J14: 107.3 | K14: 106.1 | L14: 103.7 | M14: 104 | N14: 107.4 | O14: 109.9 | P14: 108.1 | Q14: 108.1 | R14: 108.8 | S14: 107.9 | T14: 108.6 | V14: 107.5 | W14: 106.8 | X14: 105.7 | Y14: 104.1 | Z14: 105 | AA14: 105.5 | AB14: 102.1 | AC14: 104.8 | AD14: 107.2
A15: Urban | B15: 2013 | C15: May | D15: 115.4 | E15: 114.2 | F15: 102.7 | G15: 105.5 | H15: 101.5 | I15: 110.6 | J15: 123.7 | K15: 105.2 | L15: 101.9 | M15: 105 | N15: 109.1 | O15: 111.3 | P15: 111.1 | Q15: 109.8 | R15: 108.5 | S15: 106.7 | T15: 108.3 | U15: 100.5 | V15: 107.2 | W15: 107.1 | X15: 106.2 | Y15: 103.9 | Z15: 104.6 | AA15: 105.7 | AB15: 102.6 | AC15: 104.9 | AD15: 106.6
A16: Rural+Urban | B16: 2013 | C16: May | D16: 112.3 | E16: 111.3 | F16: 104.7 | G16: 106.8 | H16: 103.9 | I16: 109.3 | J16: 112.9 | K16: 105.8 | L16: 103.1 | M16: 104.3 | N16: 108.1 | O16: 110.5 | P16: 109.2 | Q16: 108.6 | R16: 108.7 | S16: 107.4 | T16: 108.5 | U16: 100.5 | V16: 107.4 | W16: 106.9 | X16: 105.9 | Y16: 104 | Z16: 104.8 | AA16: 105.6 | AB16: 102.3 | AC16: 104.8 | AD16: 106.9
A17: Rural | B17: 2013 | C17: June | D17: 112.3 | E17: 112.1 | F17: 108.1 | G17: 108.3 | H17: 105.9 | I17: 109.2 | J17: 118 | K17: 106.8 | L17: 104.1 | M17: 105.4 | N17: 108.2 | O17: 111 | P17: 110.6 | Q17: 109 | R17: 109.7 | S17: 108.8 | T17: 109.5 | V17: 108.5 | W17: 107.5 | X17: 106.3 | Y17: 105 | Z17: 105.6 | AA17: 106.5 | AB17: 102.5 | AC17: 105.5 | AD17: 108.9
A18: Urban | B18: 2013 | C18: June | D18: 117 | E18: 120.1 | F18: 112.5 | G18: 107.3 | H18: 101.3 | I18: 112.4 | J18: 143.6 | K18: 105.4 | L18: 101.4 | M18: 106.4 | N18: 110 | O18: 112.2 | P18: 115 | Q18: 110.9 | R18: 109.2 | S18: 107.2 | T18: 108.9 | U18: 106.6 | V18: 108 | W18: 107.7 | X18: 106.5 | Y18: 105.2 | Z18: 105.2 | AA18: 108.1 | AB18: 103.3 | AC18: 106.1 | AD18: 109.7
A19: Rural+Urban | B19: 2013 | C19: June | D19: 113.8 | E19: 114.9 | F19: 109.8 | G19: 107.9 | H19: 104.2 | I19: 110.7 | J19: 126.7 | K19: 106.3 | L19: 103.2 | M19: 105.7 | N19: 109 | O19: 111.6 | P19: 112.2 | Q19: 109.5 | R19: 109.5 | S19: 108.1 | T19: 109.3 | U19: 106.6 | V19: 108.3 | W19: 107.6 | X19: 106.4 | Y19: 105.1 | Z19: 105.4 | AA19: 107.4 | AB19: 102.8 | AC19: 105.8 | AD19: 109.3
A20: Rural | B20: 2013 | C20: July | D20: 113.4 | E20: 114.9 | F20: 110.5 | G20: 109.3 | H20: 106.2 | I20: 110.3 | J20: 129.2 | K20: 107.1 | L20: 104.3 | M20: 106.4 | N20: 109.1 | O20: 112.1 | P20: 113.1 | Q20: 109.8 | R20: 110.5 | S20: 109.5 | T20: 110.3 | V20: 109.5 | W20: 108.3 | X20: 106.9 | Y20: 106.8 | Z20: 106.4 | AA20: 107.8 | AB20: 102.5 | AC20: 106.5 | AD20: 110.7
A21: Urban | B21: 2013 | C21: July | D21: 117.8 | E21: 119.2 | F21: 114 | G21: 108.3 | H21: 101.1 | I21: 113.2 | J21: 160.9 | K21: 105.1 | L21: 101.3 | M21: 107.5 | N21: 110.4 | O21: 113.1 | P21: 117.5 | Q21: 111.7 | R21: 109.8 | S21: 107.8 | T21: 109.5 | U21: 107.7 | V21: 108.6 | W21: 108.1 | X21: 107.1 | Y21: 107.3 | Z21: 105.9 | AA21: 110.1 | AB21: 103.2 | AC21: 107.3 | AD21: 111.4
A22: Rural+Urban | B22: 2013 | C22: July | D22: 114.8 | E22: 116.4 | F22: 111.9 | G22: 108.9 | H22: 104.3 | I22: 111.7 | J22: 140 | K22: 106.4 | L22: 103.3 | M22: 106.8 | N22: 109.6 | O22: 112.6 | P22: 114.7 | Q22: 110.3 | R22: 110.2 | S22: 108.8 | T22: 110 | U22: 107.7 | V22: 109.2 | W22: 108.2 | X22: 107 | Y22: 107.1 | Z22: 106.1 | AA22: 109.1 | AB22: 102.8 | AC22: 106.9 | AD22: 111
A23: Rural | B23: 2013 | C23: August | D23: 114.3 | E23: 115.4 | F23: 111.1 | G23: 110 | H23: 106.4 | I23: 110.8 | J23: 138.9 | K23: 107.4 | L23: 104.1 | M23: 106.9 | N23: 109.7 | O23: 112.6 | P23: 114.9 | Q23: 110.7 | R23: 111.3 | S23: 110.2 | T23: 111.1 | V23: 109.9 | W23: 108.7 | X23: 107.5 | Y23: 107.8 | Z23: 106.8 | AA23: 108.7 | AB23: 105 | AC23: 107.5 | AD23: 112.1
A24: Urban | B24: 2013 | C24: August | D24: 118.3 | E24: 120.4 | F24: 112.7 | G24: 108.9 | H24: 101.1 | I24: 108.7 | J24: 177 | K24: 104.7 | L24: 101 | M24: 108.5 | N24: 110.9 | O24: 114.3 | P24: 119.6 | Q24: 112.4 | R24: 110.6 | S24: 108.3 | T24: 110.2 | U24: 108.9 | V24: 109.3 | W24: 108.7 | X24: 107.6 | Y24: 108.1 | Z24: 106.5 | AA24: 110.8 | AB24: 106 | AC24: 108.3 | AD24: 112.7
A25: Rural+Urban | B25: 2013 | C25: August | D25: 115.6 | E25: 117.2 | F25: 111.7 | G25: 109.6 | H25: 104.5 | I25: 109.8 | J25: 151.8 | K25: 106.5 | L25: 103.1 | M25: 107.4 | N25: 110.2 | O25: 113.4 | P25: 116.6 | Q25: 111.2 | R25: 111 | S25: 109.4 | T25: 110.7 | U25: 108.9 | V25: 109.7 | W25: 108.7 | X25: 107.5 | Y25: 108 | Z25: 106.6 | AA25: 109.9 | AB25: 105.4 | AC25: 107.9 | AD25: 112.4
A26: Rural | B26: 2013 | C26: September | D26: 115.4 | E26: 115.7 | F26: 111.7 | G26: 111 | H26: 107.4 | I26: 110.9 | J26: 154 | K26: 108.1 | L26: 104.2 | M26: 107.9 | N26: 110.4 | O26: 114 | P26: 117.8 | Q26: 111.7 | R26: 112.7 | S26: 111.4 | T26: 112.5 | V26: 111.1 | W26: 109.6 | X26: 108.3 | Y26: 109.3 | Z26: 107.7 | AA26: 109.8 | AB26: 106.7 | AC26: 108.7 | AD26: 114.2
A27: Urban | B27: 2013 | C27: September | D27: 118.6 | E27: 119.1 | F27: 113.2 | G27: 109.6 | H27: 101.7 | I27: 103.2 | J27: 174.3 | K27: 105.1 | L27: 100.8 | M27: 109.1 | N27: 111.1 | O27: 115.4 | P27: 119.2 | Q27: 112.9 | R27: 111.4 | S27: 109 | T27: 111.1 | U27: 109.7 | V27: 109.5 | W27: 109.6 | X27: 107.9 | Y27: 110.4 | Z27: 107.4 | AA27: 111.2 | AB27: 106.9 | AC27: 109.4 | AD27: 113.2
A28: Rural+Urban | B28: 2013 | C28: September | D28: 116.4 | E28: 116.9 | F28: 112.3 | G28: 110.5 | H28: 105.3 | I28: 107.3 | J28: 160.9 | K28: 107.1 | L28: 103.1 | M28: 108.3 | N28: 110.7 | O28: 114.6 | P28: 118.3 | Q28: 112 | R28: 112.2 | S28: 110.4 | T28: 111.9 | U28: 109.7 | V28: 110.5 | W28: 109.6 | X28: 108.1 | Y28: 109.9 | Z28: 107.5 | AA28: 110.6 | AB28: 106.8 | AC28: 109 | AD28: 113.7
A29: Rural | B29: 2013 | C29: October | D29: 116.3 | E29: 115.4 | F29: 112.6 | G29: 111.7 | H29: 107.7 | I29: 113.2 | J29: 164.9 | K29: 108.3 | L29: 103.9 | M29: 108.2 | N29: 111.1 | O29: 114.9 | P29: 119.8 | Q29: 112.2 | R29: 113.6 | S29: 112.3 | T29: 113.4 | V29: 111.6 | W29: 110.4 | X29: 108.9 | Y29: 109.3 | Z29: 108.3 | AA29: 110.2 | AB29: 107.5 | AC29: 109.1 | AD29: 115.5
A30: Urban | B30: 2013 | C30: October | D30: 118.9 | E30: 118.1 | F30: 114.5 | G30: 110.4 | H30: 102.3 | I30: 106.2 | J30: 183.5 | K30: 105.3 | L30: 100.2 | M30: 109.6 | N30: 111.4 | O30: 116 | P30: 120.8 | Q30: 113.5 | R30: 112.5 | S30: 109.7 | T30: 112 | U30: 110.5 | V30: 109.7 | W30: 110.2 | X30: 108.2 | Y30: 109.7 | Z30: 108 | AA30: 111.3 | AB30: 107.3 | AC30: 109.4 | AD30: 114
A31: Rural+Urban | B31: 2013 | C31: October | D31: 117.1 | E31: 116.3 | F31: 113.3 | G31: 111.2 | H31: 105.7 | I31: 109.9 | J31: 171.2 | K31: 107.3 | L31: 102.7 | M31: 108.7 | N31: 111.2 | O31: 115.4 | P31: 120.2 | Q31: 112.5 | R31: 113.2 | S31: 111.2 | T31: 112.8 | U31: 110.5 | V31: 110.9 | W31: 110.3 | X31: 108.6 | Y31: 109.5 | Z31: 108.1 | AA31: 110.8 | AB31: 107.4 | AC31: 109.2 | AD31: 114.8
A32: Rural | B32: 2013 | C32: November | D32: 117.3 | E32: 114.9 | F32: 116.2 | G32: 112.8 | H32: 108.9 | I32: 116.6 | J32: 178.1 | K32: 109.1 | L32: 103.6 | M32: 109 | N32: 111.8 | O32: 116 | P32: 122.5 | Q32: 112.8 | R32: 114.6 | S32: 113.1 | T32: 114.4 | V32: 112.6 | W32: 111.3 | X32: 109.7 | Y32: 109.6 | Z32: 108.7 | AA32: 111 | AB32: 108.2 | AC32: 109.8 | AD32: 117.4
A33: Urban | B33: 2013 | C33: November | D33: 119.8 | E33: 116.3 | F33: 122.6 | G33: 112 | H33: 103.2 | I33: 110 | J33: 192.8 | K33: 106.3 | L33: 99.5 | M33: 110.3 | N33: 111.8 | O33: 117.1 | P33: 122.9 | Q33: 114.1 | R33: 113.5 | S33: 110.3 | T33: 113 | U33: 111.1 | V33: 110 | W33: 110.9 | X33: 108.6 | Y33: 109.5 | Z33: 108.5 | AA33: 111.3 | AB33: 107.9 | AC33: 109.6 | AD33: 115
A34: Rural+Urban | B34: 2013 | C34: November | D34: 118.1 | E34: 115.4 | F34: 118.7 | G34: 112.5 | H34: 106.8 | I34: 113.5 | J34: 183.1 | K34: 108.2 | L34: 102.2 | M34: 109.4 | N34: 111.8 | O34: 116.5 | P34: 122.6 | Q34: 113.1 | R34: 114.2 | S34: 111.9 | T34: 113.8 | U34: 111.1 | V34: 111.6 | W34: 111.1 | X34: 109.3 | Y34: 109.5 | Z34: 108.6 | AA34: 111.2 | AB34: 108.1 | AC34: 109.7 | AD34: 116.3
A35: Rural | B35: 2013 | C35: December | D35: 118.4 | E35: 115.9 | F35: 120.4 | G35: 113.8 | H35: 109.5 | I35: 115.5 | J35: 145.7 | K35: 109.5 | L35: 102.9 | M35: 109.8 | N35: 112.1 | O35: 116.8 | P35: 118.7 | Q35: 113.6 | R35: 115.8 | S35: 114 | T35: 115.5 | V35: 112.8 | W35: 112.1 | X35: 110.1 | Y35: 109.9 | Z35: 109.2 | AA35: 111.6 | AB35: 108.1 | AC35: 110.1 | AD35: 115.5
A36: Urban | B36: 2013 | C36: December | D36: 120.5 | E36: 118.1 | F36: 128.5 | G36: 112.8 | H36: 103.4 | I36: 110.7 | J36: 144.8 | K36: 107.1 | L36: 98.6 | M36: 111.9 | N36: 112.1 | O36: 118.1 | P36: 117.8 | Q36: 115 | R36: 114.2 | S36: 110.9 | T36: 113.7 | U36: 110.7 | V36: 110.4 | W36: 111.3 | X36: 109 | Y36: 109.7 | Z36: 108.9 | AA36: 111.4 | AB36: 107.7 | AC36: 109.8 | AD36: 113.3
A37: Rural+Urban | B37: 2013 | C37: December | D37: 119.1 | E37: 116.7 | F37: 123.5 | G37: 113.4 | H37: 107.3 | I37: 113.3 | J37: 145.4 | K37: 108.7 | L37: 101.5 | M37: 110.5 | N37: 112.1 | O37: 117.4 | P37: 118.4 | Q37: 114 | R37: 115.2 | S37: 112.7 | T37: 114.8 | U37: 110.7 | V37: 111.9 | W37: 111.7 | X37: 109.7 | Y37: 109.8 | Z37: 109 | AA37: 111.5 | AB37: 107.9 | AC37: 110 | AD37: 114.5
A38: Rural | B38: 2014 | C38: January | D38: 118.9 | E38: 117.1 | F38: 120.5 | G38: 114.4 | H38: 109 | I38: 115.5 | J38: 123.9 | K38: 109.6 | L38: 101.8 | M38: 110.2 | N38: 112.4 | O38: 117.3 | P38: 116 | Q38: 114 | R38: 116.5 | S38: 114.5 | T38: 116.2 | V38: 113 | W38: 112.6 | X38: 110.6 | Y38: 110.5 | Z38: 109.6 | AA38: 111.8 | AB38: 108.3 | AC38: 110.6 | AD38: 114.2
A39: Urban | B39: 2014 | C39: January | D39: 121.2 | E39: 122 | F39: 129.9 | G39: 113.6 | H39: 102.9 | I39: 112.1 | J39: 118.9 | K39: 107.5 | L39: 96.9 | M39: 112.7 | N39: 112.1 | O39: 119 | P39: 115.5 | Q39: 115.7 | R39: 114.8 | S39: 111.3 | T39: 114.3 | U39: 111.6 | V39: 111 | W39: 111.9 | X39: 109.7 | Y39: 110.8 | Z39: 109.8 | AA39: 111.5 | AB39: 108 | AC39: 110.5 | AD39: 112.9
A40: Rural+Urban | B40: 2014 | C40: January | D40: 119.6 | E40: 118.8 | F40: 124.1 | G40: 114.1 | H40: 106.8 | I40: 113.9 | J40: 122.2 | K40: 108.9 | L40: 100.2 | M40: 111 | N40: 112.3 | O40: 118.1 | P40: 115.8 | Q40: 114.5 | R40: 115.8 | S40: 113.2 | T40: 115.4 | U40: 111.6 | V40: 112.2 | W40: 112.3 | X40: 110.3 | Y40: 110.7 | Z40: 109.7 | AA40: 111.6 | AB40: 108.2 | AC40: 110.6 | AD40: 113.6
...

Sheet Data Quality Check
A1: Data Cleaning & Quality Check
E2: ← Dashboard
A3: Check | B3: Before Cleaning | C3: Action Taken | D3: After Cleaning
A4: Rows | B4: 372 | C4: No rows removed | D4: 372
A5: Columns | B5: 30 | C5: No columns removed | D5: 30
A6: Duplicate rows | B6: 0 | C6: Checked; none found | D6: 0
A7: Month typo | B7: Marcrh (1 row) | C7: Corrected to March | D7: No invalid month labels
A8: Month whitespace | B8: November + trailing space | C8: Trimmed text | D8: All month labels standardized
A9: Housing '-' values | B9: 4 | C9: Converted '-' to missing numeric value | D9: Missing values retained as blank/NA
A10: Numeric CPI fields | B10: Housing was text/object | C10: Converted CPI measure columns to numeric | D10: Housing and all CPI measures numeric
A13: Missing-value policy
A14: Missing values are not automatically replaced. They remain blank/NA unless a specific requires an imputation method (for example, a moving average). This prevents fabricated CPI values.
A18: Excel / Data Cleaning Method Notes
A19: TRIM / text standardization | B19: Whitespace was removed from text fields such as Month and Sector so categories match consistently.
A20: Numeric conversion | B20: CPI measurement fields were converted to numeric data types; non-numeric '-' values were treated as missing.
A21: Missing values | B21: Missing values are retained unless a specific requires an estimation method. Any such estimation is documented directly in the relevant analysis sheet.

Sheet Category Mapping
A1: Detailed CPI Category | B1: Broader Category | C1: Mapping Logic
A2: Cereals and products | B2: Food | C2: Food & beverages component | D2: ← Dashboard
A3: Meat and fish | B3: Food | C3: Food & beverages component
A4: Egg | B4: Food | C4: Food & beverages component
A5: Milk and products | B5: Food | C5: Food & beverages component
A6: Oils and fats | B6: Food | C6: Food & beverages component
A7: Fruits | B7: Food | C7: Food & beverages component
A8: Vegetables | B8: Food | C8: Food & beverages component
A9: Pulses and products | B9: Food | C9: Food & beverages component
A10: Sugar and Confectionery | B10: Food | C10: Food & beverages component
A11: Spices | B11: Food | C11: Food & beverages component
A12: Non-alcoholic beverages | B12: Food | C12: Food & beverages component
A13: Prepared meals, snacks, sweets etc. | B13: Food | C13: Food & beverages component
A14: Pan, tobacco and intoxicants | B14: Pan, Tobacco & Intoxicants | C14: Standalone broad category
... A24: Personal care and effects | B24: Personal Care & Effects | C24: Miscellaneous component
A27: Q1 Note
A28: Aggregate/index columns are intentionally excluded from this mapping to avoid double-counting.
A29: Excluded from component-level calculations: Food and beverages, Clothing and footwear, Miscellaneous, General index.
A30: The case study specifies equal weights across categories; the calculation methodology will be documented in the Q1 Analysis sheet.

Sheet Q1 Analysis
A1: India CPI Inflation Case Study — Q1 Analysis
E2: ← Dashboard
A3: Question | B3: Based on the latest month's data, identifing the contribution of different broader categories towards the CPI calculation.
A6: Latest Year | B6: 2023 | C6: Latest Month | D6: May
A7: Sector Used | B7: 32
A9: Calculation
A10: For each broader category, the underlying detailed CPI index values are averaged using equal weights, as instructed by the case study. Contribution % = Broader Category Index ÷ Sum of Broader Category Indices × 100. Aggregate/index columns are excluded to avoid double-counting.
A14: Broader Category | B14: Components Used | C14: Category Index | D14: Contribution %
A15: ='Q1 Calculation'!A7 -> Food | B15: ='Q1 Calculation'!C7 -> 12 | C15: ='Q1 Calculation'!E7 -> 175.78182 | D15: ='Q1 Calculation'!F7 -> 0.088873772
A16: ='Q1 Calculation'!A8 -> Pan, Tobacco & Intoxicants | B16: ='Q1 Calculation'!C8 -> 1 | C16: ='Q1 Calculation'!E8 -> 201 | D16: ='Q1 Calculation'!F8 -> 0.10162387
A17: ='Q1 Calculation'!A9 -> Clothing & Footwear | B17: ='Q1 Calculation'!C9 -> 2 | C17: ='Q1 Calculation'!E9 -> 183.5 | D17: ='Q1 Calculation'!F9 -> 0.092776018
A18: ='Q1 Calculation'!A10 -> Housing | B18: ='Q1 Calculation'!C10 -> 1 | C18: ='Q1 Calculation'!E10 -> 175.6 | D18: ='Q1 Calculation'!F10 -> 0.088781847
A19: ='Q1 Calculation'!A11 -> Fuel & Light | B19: ='Q1 Calculation'!C11 -> 1 | C19: ='Q1 Calculation'!E11 -> 182.8 | D19: ='Q1 Calculation'!F11 -> 0.092422104
A20: ='Q1 Calculation'!A12 -> Household Goods & Services | B20: ='Q1 Calculation'!C12 -> 1 | C20: ='Q1 Calculation'!E12 -> 175.2 | D20: ='Q1 Calculation'!F12 -> 0.08857961
A21: ='Q1 Calculation'!A13 -> Health | B21: ='Q1 Calculation'!C13 -> 1 | C21: ='Q1 Calculation'!E13 -> 185.7 | D21: ='Q1 Calculation'!F13 -> 0.093888319
A22: ='Q1 Calculation'!A14 -> Transport & Communication | B22: ='Q1 Calculation'!C14 -> 1 | C22: ='Q1 Calculation'!E14 -> 164.8 | D22: ='Q1 Calculation'!F14 -> 0.08332146
A23: ='Q1 Calculation'!A15 -> Recreation & Amusement | B23: ='Q1 Calculation'!C15 -> 1 | C23: ='Q1 Calculation'!E15 -> 171.2 | D23: ='Q1 Calculation'!F15 -> 0.086557244
A24: ='Q1 Calculation'!A16 -> Education | B24: ='Q1 Calculation'!C16 -> 1 | C24: ='Q1 Calculation'!E16 -> 177.1 | D24: ='Q1 Calculation'!F16 -> 0.089540234
A25: ='Q1 Calculation'!A17 -> Personal Care & Effects | B25: ='Q1 Calculation'!C17 -> 1 | C25: ='Q1 Calculation'!E17 -> 185.2 | D25: ='Q1 Calculation'!F17 -> 0.093635524
A26: Total | C26: =SUM(C15:C25) -> 1977.8818 | D26: =SUM(D15:D25) -> 1
A29: Key Result | B29: =INDEX(A15:A25,MATCH(MAX(D15:D25),D15:D25,0)) -> Pan, Tobacco & Intoxicants | D29: =MAX(D15:D25) -> 0.10162387
A30: Highest Contributing Category | B30: Pan, Tobacco & Intoxicants | C30: Contribution | D30: 0.10154507
A32: Interview Insight
A33: In May 2023, under the case study's equal-weight assumption, Pan, Tobacco & Intoxicants has the highest calculated contribution to the CPI basket at 10.15%.
A37: Function / Method Notes
A38: AVERAGE | B38: Used in Q1 Calculation to derive each broader category's equal-weighted index from its detailed CPI components.
A39: SUM | B39: Used to total broader-category indices and to verify that contribution percentages sum to 100%.
A40: IF | B40: Used for the contribution validation check, returning OK/CHECK based on whether the total equals 100%.
A41: Key-result formulas
A42: INDEX + MATCH + MAX | B42: Finds the category name associated with the highest Contribution %; MAX finds the highest contribution.

Sheet Q1 Calculation
A1: Q1 — CPI Broad Category Calculation
L2: ← Dashboard
A3: Latest Period | B3: May 2023 | D3: Sector | E3: Rural+Urban
J5: Latest Period Component Values
A6: Broader Category | B6: Underlying Components | C6: Components Used | D6: Sum of Component Indices | E6: Equal-Weighted Category Index | F6: Contribution % | G6: Contribution Check | H6: Formula / Logic | J6: Detailed Category | K6: Index Value
A7: Food | B7: Cereals and products, Meat and fish, Egg, Milk and products, Oils and fats, Fruits, Vegetables, Pulses and products, Sugar and Confectionery, Spices, Non-alcoholic beverages, Prepared meals, snacks, sweets etc. | C7: 12 | D7: =$K$7+$K$8+$K$9+$K$10+$K$11+$K$12+$K$13+$K$14+$K$16+$K$17 -> 1810.9 | E7: =AVERAGE($K$7,$K$8,$K$9,$K$10,$K$11,$K$12,$K$13,$K$14,$K$15,$K$16,$K$17) -> 175.78182 | F7: =E7/SUM($E$7:$E$17) -> 0.088873772 | G7: =IF(ABS(SUM($F$7:$F$17)-1)<0.000001,"OK","CHECK") -> OK | H7: SUM of underlying component indices → total component index; AVERAGE of underlying component indices → equal-weighted broader-category index; contribution = category index ÷ SUM of all broader-category indices. | J7: Cereals and products | K7: 173.7
A8: Pan, Tobacco & Intoxicants | B8: Pan, tobacco and intoxicants | C8: 1 | D8: =$K$19 -> 201 | E8: =D8/C8 -> 201 | F8: =E8/SUM($E$7:$E$17) -> 0.10162387 | G8: =IF(ABS(SUM($F$7:$F$17)-1)<0.000001,"OK","CHECK") -> OK | H8: Average underlying detailed CPI indices; contribution = category index ÷ sum of category indices | J8: Meat and fish | K8: 214.3
A9: Clothing & Footwear | B9: Clothing, Footwear | C9: 2 | D9: =$K$20+$K$21 -> 367 | E9: =AVERAGE($K$20,$K$21) -> 183.5 | F9: =E9/SUM($E$7:$E$17) -> 0.092776018 | G9: =IF(ABS(SUM($F$7:$F$17)-1)<0.000001,"OK","CHECK") -> OK | H9: SUM of underlying component indices → total component index; AVERAGE of underlying component indices → equal-weighted broader-category index; contribution = category index ÷ SUM of all broader-category indices. | J9: Egg | K9: 173.2
A10: Housing | B10: Housing | C10: 1 | D10: =$K$22 -> 175.6 | E10: =AVERAGE($K$22) -> 175.6 | F10: =E10/SUM($E$7:$E$17) -> 0.088781847 | G10: =IF(ABS(SUM($F$7:$F$17)-1)<0.000001,"OK","CHECK") -> OK | H10: SUM of underlying component indices → total component index; AVERAGE of underlying component indices → equal-weighted broader-category index; contribution = category index ÷ SUM of all broader-category indices. | J10: Milk and products | K10: 179.5
A11: Fuel & Light | B11: Fuel and light | C11: 1 | D11: =$K$23 -> 182.8 | E11: =AVERAGE($K$23) -> 182.8 | F11: =E11/SUM($E$7:$E$17) -> 0.092422104 | G11: =IF(ABS(SUM($F$7:$F$17)-1)<0.000001,"OK","CHECK") -> OK | H11: SUM of underlying component indices → total component index; AVERAGE of underlying component indices → equal-weighted broader-category index; contribution = category index ÷ SUM of all broader-category indices. | J11: Oils and fats | K11: 170
A12: Household Goods & Services | B12: Household goods and services | C12: 1 | D12: =$K$24 -> 175.2 | E12: =AVERAGE($K$24) -> 175.2 | F12: =E12/SUM($E$7:$E$17) -> 0.08857961 | G12: =IF(ABS(SUM($F$7:$F$17)-1)<0.000001,"OK","CHECK") -> OK | H12: SUM of underlying component indices → total component index; AVERAGE of underlying component indices → equal-weighted broader-category index; contribution = category index ÷ SUM of all broader-category indices. | J12: Fruits | K12: 172.2
A13: Health | B13: Health | C13: 1 | D13: =$K$25 -> 185.7 | E13: =AVERAGE($K$25) -> 185.7 | F13: =E13/SUM($E$7:$E$17) -> 0.093888319 | G13: =IF(ABS(SUM($F$7:$F$17)-1)<0.000001,"OK","CHECK") -> OK | H13: SUM of underlying component indices → total component index; AVERAGE of underlying component indices → equal-weighted broader-category index; contribution = category index ÷ SUM of all broader-category indices. | J13: Vegetables | K13: 161
A14: Transport & Communication | B14: Transport and communication | C14: 1 | D14: =$K$26 -> 164.8 | E14: =AVERAGE($K$26) -> 164.8 | F14: =E14/SUM($E$7:$E$17) -> 0.08332146 | G14: =IF(ABS(SUM($F$7:$F$17)-1)<0.000001,"OK","CHECK") -> OK | H14: SUM of underlying component indices → total component index; AVERAGE of underlying component indices → equal-weighted broader-category index; contribution = category index ÷ SUM of all broader-category indices. | J14: Pulses and products | K14: 175.6
A15: Recreation & Amusement | B15: Recreation and amusement | C15: 1 | D15: =$K$27 -> 171.2 | E15: =AVERAGE($K$27) -> 171.2 | F15: =E15/SUM($E$7:$E$17) -> 0.086557244 | G15: =IF(ABS(SUM($F$7:$F$17)-1)<0.000001,"OK","CHECK") -> OK | H15: SUM of underlying component indices → total component index; AVERAGE of underlying component indices → equal-weighted broader-category index; contribution = category index ÷ SUM of all broader-category indices. | J15: Sugar and Confectionery | K15: 122.7
A16: Education | B16: Education | C16: 1 | D16: =$K$28 -> 177.1 | E16: =AVERAGE($K$28) -> 177.1 | F16: =E16/SUM($E$7:$E$17) -> 0.089540234 | G16: =IF(ABS(SUM($F$7:$F$17)-1)<0.000001,"OK","CHECK") -> OK | H16: SUM of underlying component indices → total component index; AVERAGE of underlying component indices → equal-weighted broader-category index; contribution = category index ÷ SUM of all broader-category indices. | J16: Spices | K16: 218
A17: Personal Care & Effects | B17: Personal care and effects | C17: 1 | D17: =$K$29 -> 185.2 | E17: =AVERAGE($K$29) -> 185.2 | F17: =E17/SUM($E$7:$E$17) -> 0.093635524 | G17: =IF(ABS(SUM($F$7:$F$17)-1)<0.000001,"OK","CHECK") -> OK | H17: SUM of underlying component indices → total component index; AVERAGE of underlying component indices → equal-weighted broader-category index; contribution = category index ÷ SUM of all broader-category indices. | J17: Non-alcoholic beverages | K17: 173.4
A18: TOTAL | C18: =SUM(C7:C17) -> 23 | D18: =SUM(D7:D17) -> 3796.5 | E18: =SUM(E7:E17) -> 1977.8818 | F18: =SUM(F7:F17) -> 1 | G18: =IF(ABS(F18-1)<0.000001,"PASS — 100%","CHECK") -> PASS — 100% | J18: Prepared meals, snacks, sweets etc. | K18: 194.2
J19: Pan, tobacco and intoxicants | K19: 201
J20: Clothing | K20: 187.3
A21: Q1 Answer | J21: Footwear | K21: 179.7
A22: Highest Contribution | B22: =INDEX(A7:A17,MATCH(MAX(F7:F17),F7:F17,0)) -> Pan, Tobacco & Intoxicants | C22: Contribution | D22: =MAX(F7:F17) -> 0.10162387 | J22: Housing | K22: 175.6
J23: Fuel and light | K23: 182.8
J24: Household goods and services | K24: 175.2
A25: Note | B25: The calculation follows the case-study instruction to use equal weights. Detailed CPI component indices are averaged within each broader category; aggregate columns such as Food and beverages, Clothing and footwear, Miscellaneous, and General index are excluded. | J25: Health | K25: 185.7
J26: Transport and communication | K26: 164.8
J27: Recreation and amusement | K27: 171.2
J28: Education | K28: 177.1
J29: Personal care and effects | K29: 185.2
A32: Excel Function / Calculation Guide
A33: SUM | B33: Adds the underlying CPI component indices within each broader category and totals the category results.
A34: AVERAGE | B34: Calculates the equal-weighted broader-category CPI index from its underlying detailed categories.
A35: SUM + division | B35: Calculates each category's contribution as Category Index ÷ SUM of all broader-category indices.
A36: IF + SUM | B36: Checks whether all contribution percentages add to 100%.

Sheet Q1 Contribution
A1: Q1 — Contribution of Broader Categories
G2: ← Dashboard
A3: Latest Period | B3: May 2023 | D3: Sector | E3: Rural+Urban
A5: Rank | B5: Broader Category | C5: Category Index | D5: Contribution % | E5: Contribution Check | F5: Interpretation
A6: =RANK(D6,$D$6:$D$16,0) -> 7 | B6: Food | C6: ='Q1 Calculation'!E7 -> 175.78182 | D6: ='Q1 Calculation'!F7 -> 0.088873772 | E6: =IF(ABS(SUM($D$6:$D$16)-1)<0.000001,"OK","CHECK") -> OK | F6: =IF(D6=MAX($D$6:$D$16),"Highest contribution","")
A7: =RANK(D7,$D$6:$D$16,0) -> 1 | B7: Pan, Tobacco & Intoxicants | C7: ='Q1 Calculation'!E8 -> 201 | D7: ='Q1 Calculation'!F8 -> 0.10162387 | E7: =IF(ABS(SUM($D$6:$D$16)-1)<0.000001,"OK","CHECK") -> OK | F7: =IF(D7=MAX($D$6:$D$16),"Highest contribution","") -> Highest contribution
A8: =RANK(D8,$D$6:$D$16,0) -> 4 | B8: Clothing & Footwear | C8: ='Q1 Calculation'!E9 -> 183.5 | D8: ='Q1 Calculation'!F9 -> 0.092776018 | E8: =IF(ABS(SUM($D$6:$D$16)-1)<0.000001,"OK","CHECK") -> OK | F8: =IF(D8=MAX($D$6:$D$16),"Highest contribution","")
A9: =RANK(D9,$D$6:$D$16,0) -> 8 | B9: Housing | C9: ='Q1 Calculation'!E10 -> 175.6 | D9: ='Q1 Calculation'!F10 -> 0.088781847 | E9: =IF(ABS(SUM($D$6:$D$16)-1)<0.000001,"OK","CHECK") -> OK | F9: =IF(D9=MAX($D$6:$D$16),"Highest contribution","")
A10: =RANK(D10,$D$6:$D$16,0) -> 5 | B10: Fuel & Light | C10: ='Q1 Calculation'!E11 -> 182.8 | D10: ='Q1 Calculation'!F11 -> 0.092422104 | E10: =IF(ABS(SUM($D$6:$D$16)-1)<0.000001,"OK","CHECK") -> OK | F10: =IF(D10=MAX($D$6:$D$16),"Highest contribution","")
A11: =RANK(D11,$D$6:$D$16,0) -> 9 | B11: Household Goods & Services | C11: ='Q1 Calculation'!E12 -> 175.2 | D11: ='Q1 Calculation'!F12 -> 0.08857961 | E11: =IF(ABS(SUM($D$6:$D$16)-1)<0.000001,"OK","CHECK") -> OK | F11: =IF(D11=MAX($D$6:$D$16),"Highest contribution","")
A12: =RANK(D12,$D$6:$D$16,0) -> 2 | B12: Health | C12: ='Q1 Calculation'!E13 -> 185.7 | D12: ='Q1 Calculation'!F13 -> 0.093888319 | E12: =IF(ABS(SUM($D$6:$D$16)-1)<0.000001,"OK","CHECK") -> OK | F12: =IF(D12=MAX($D$6:$D$16),"Highest contribution","")
A13: =RANK(D13,$D$6:$D$16,0) -> 11 | B13: Transport & Communication | C13: ='Q1 Calculation'!E14 -> 164.8 | D13: ='Q1 Calculation'!F14 -> 0.08332146 | E13: =IF(ABS(SUM($D$6:$D$16)-1)<0.000001,"OK","CHECK") -> OK | F13: =IF(D13=MAX($D$6:$D$16),"Highest contribution","")
A14: =RANK(D14,$D$6:$D$16,0) -> 10 | B14: Recreation & Amusement | C14: ='Q1 Calculation'!E15 -> 171.2 | D14: ='Q1 Calculation'!F15 -> 0.086557244 | E14: =IF(ABS(SUM($D$6:$D$16)-1)<0.000001,"OK","CHECK") -> OK | F14: =IF(D14=MAX($D$6:$D$16),"Highest contribution","")
A15: =RANK(D15,$D$6:$D$16,0) -> 6 | B15: Education | C15: ='Q1 Calculation'!E16 -> 177.1 | D15: ='Q1 Calculation'!F16 -> 0.089540234 | E15: =IF(ABS(SUM($D$6:$D$16)-1)<0.000001,"OK","CHECK") -> OK | F15: =IF(D15=MAX($D$6:$D$16),"Highest contribution","")
A16: =RANK(D16,$D$6:$D$16,0) -> 3 | B16: Personal Care & Effects | C16: ='Q1 Calculation'!E17 -> 185.2 | D16: ='Q1 Calculation'!F17 -> 0.093635524 | E16: =IF(ABS(SUM($D$6:$D$16)-1)<0.000001,"OK","CHECK") -> OK | F16: =IF(D16=MAX($D$6:$D$16),"Highest contribution","")
B17: TOTAL | C17: =SUM(C6:C16) -> 1977.8818 | D17: =SUM(D6:D16) -> 1 | E17: =IF(ABS(D17-1)<0.000001,"PASS — 100%","CHECK") -> PASS — 100%
A20: Key Takeaway
A21: Highest Contributor | B21: =INDEX(B6:B16,MATCH(MAX(D6:D16),D6:D16,0)) -> Pan, Tobacco & Intoxicants | C21: Contribution | D21: =MAX(D6:D16) -> 0.10162387
A24: Function / Method Notes
A25: RANK.EQ | B25: Ranks categories by Contribution % so the largest contribution receives rank 1.
A26: MAX | B26: Finds the highest Contribution % for the key result and highest-contribution flag.
A27: INDEX + MATCH | B27: Returns the category name associated with the maximum Contribution %.
A28: SUM + IF | B28: SUM checks that all contribution percentages equal 100%; IF returns the validation status.

Sheet Q1 Pivot
A1: Q1 — Pivot Table Summary
F2: ← Dashboard
A3: Latest Period | B3: May 2023 | D3: Sector | E3: Rural+Urban
A5: Rank | B5: Broader Category | C5: Category Index | D5: Contribution % | E5: Components Used
A6: =RANK(D6,$D$6:$D$16,0) -> 7 | B6: ='Q1 Calculation'!A7 -> Food | C6: ='Q1 Calculation'!E7 -> 175.78182 | D6: ='Q1 Calculation'!F7 -> 0.088873772 | E6: ='Q1 Calculation'!C7 -> 12
A7: =RANK(D7,$D$6:$D$16,0) -> 1 | B7: ='Q1 Calculation'!A8 -> Pan, Tobacco & Intoxicants | C7: ='Q1 Calculation'!E8 -> 201 | D7: ='Q1 Calculation'!F8 -> 0.10162387 | E7: ='Q1 Calculation'!C8 -> 1
A8: =RANK(D8,$D$6:$D$16,0) -> 4 | B8: ='Q1 Calculation'!A9 -> Clothing & Footwear | C8: ='Q1 Calculation'!E9 -> 183.5 | D8: ='Q1 Calculation'!F9 -> 0.092776018 | E8: ='Q1 Calculation'!C9 -> 2
A9: =RANK(D9,$D$6:$D$16,0) -> 8 | B9: ='Q1 Calculation'!A10 -> Housing | C9: ='Q1 Calculation'!E10 -> 175.6 | D9: ='Q1 Calculation'!F10 -> 0.088781847 | E9: ='Q1 Calculation'!C10 -> 1
A10: =RANK(D10,$D$6:$D$16,0) -> 5 | B10: ='Q1 Calculation'!A11 -> Fuel & Light | C10: ='Q1 Calculation'!E11 -> 182.8 | D10: ='Q1 Calculation'!F11 -> 0.092422104 | E10: ='Q1 Calculation'!C11 -> 1
A11: =RANK(D11,$D$6:$D$16,0) -> 9 | B11: ='Q1 Calculation'!A12 -> Household Goods & Services | C11: ='Q1 Calculation'!E12 -> 175.2 | D11: ='Q1 Calculation'!F12 -> 0.08857961 | E11: ='Q1 Calculation'!C12 -> 1
A12: =RANK(D12,$D$6:$D$16,0) -> 2 | B12: ='Q1 Calculation'!A13 -> Health | C12: ='Q1 Calculation'!E13 -> 185.7 | D12: ='Q1 Calculation'!F13 -> 0.093888319 | E12: ='Q1 Calculation'!C13 -> 1
A13: =RANK(D13,$D$6:$D$16,0) -> 11 | B13: ='Q1 Calculation'!A14 -> Transport & Communication | C13: ='Q1 Calculation'!E14 -> 164.8 | D13: ='Q1 Calculation'!F14 -> 0.08332146 | E13: ='Q1 Calculation'!C14 -> 1
A14: =RANK(D14,$D$6:$D$16,0) -> 10 | B14: ='Q1 Calculation'!A15 -> Recreation & Amusement | C14: ='Q1 Calculation'!E15 -> 171.2 | D14: ='Q1 Calculation'!F15 -> 0.086557244 | E14: ='Q1 Calculation'!C15 -> 1
A15: =RANK(D15,$D$6:$D$16,0) -> 6 | B15: ='Q1 Calculation'!A16 -> Education | C15: ='Q1 Calculation'!E16 -> 177.1 | D15: ='Q1 Calculation'!F16 -> 0.089540234 | E15: ='Q1 Calculation'!C16 -> 1
A16: =RANK(D16,$D$6:$D$16,0) -> 3 | B16: ='Q1 Calculation'!A17 -> Personal Care & Effects | C16: ='Q1 Calculation'!E17 -> 185.2 | D16: ='Q1 Calculation'!F17 -> 0.093635524 | E16: ='Q1 Calculation'!C17 -> 1
B17: TOTAL | C17: =SUM(C6:C16) -> 1977.8818 | D17: =SUM(D6:D16) -> 1 | E17: =SUM(E6:E16) -> 23
A20: Pivot Insight
A21: The pivot summary ranks the broader CPI categories by their calculated contribution for May 2023. The highest contributor is Pan, Tobacco & Intoxicants at 10.15%.
A26: Function / Method Notes
A27: RANK.EQ | B27: Ranks the broader categories by Contribution %.
A28: SUM | B28: Totals Category Index, Contribution %, and Components Used for validation/summary.

Sheet Q1 Visualization
A1: Q1 — CPI Contribution Visualization
G2: ← Dashboard
A3: Broader Category Contribution — May 2023
A5: Broader Category | B5: Contribution %
A6: ='Q1 Contribution'!B6 -> Food | B6: ='Q1 Contribution'!D6 -> 0.088873772
A7: ='Q1 Contribution'!B7 -> Pan, Tobacco & Intoxicants | B7: ='Q1 Contribution'!D7 -> 0.10162387
A8: ='Q1 Contribution'!B8 -> Clothing & Footwear | B8: ='Q1 Contribution'!D8 -> 0.092776018
A9: ='Q1 Contribution'!B9 -> Housing | B9: ='Q1 Contribution'!D9 -> 0.088781847
A10: ='Q1 Contribution'!B10 -> Fuel & Light | B10: ='Q1 Contribution'!D10 -> 0.092422104
A11: ='Q1 Contribution'!B11 -> Household Goods & Services | B11: ='Q1 Contribution'!D11 -> 0.08857961
A12: ='Q1 Contribution'!B12 -> Health | B12: ='Q1 Contribution'!D12 -> 0.093888319
A13: ='Q1 Contribution'!B13 -> Transport & Communication | B13: ='Q1 Contribution'!D13 -> 0.08332146
A14: ='Q1 Contribution'!B14 -> Recreation & Amusement | B14: ='Q1 Contribution'!D14 -> 0.086557244
A15: ='Q1 Contribution'!B15 -> Education | B15: ='Q1 Contribution'!D15 -> 0.089540234
A16: ='Q1 Contribution'!B16 -> Personal Care & Effects | B16: ='Q1 Contribution'!D16 -> 0.093635524
A20: Q1 Insight
A21: Pan, Tobacco & Intoxicants has the largest calculated contribution at 10.15%. Transport & Communication has the smallest at 8.33%. The result reflects the equal-weight methodology used to group detailed CPI categories.
A25: Function / Method Notes
A26: Linked formulas | B26: Visualization source values are linked to Q1 Contribution so the chart updates when the underlying calculation changes.
A27: Bar Chart | B27: Used to compare the contribution percentage across broader CPI categories; a horizontal bar chart is suitable for multiple category labels.

Sheet Q2 Calculation
A1: Q2 — YoY CPI Inflation Calculation
A3: Scope | B3: Rural+Urban — General Index (entire basket) | D3: Trend Start | E3: 2017
A5: Methodology
A6: Annual CPI is the average of monthly General Index values for Rural+Urban. YoY inflation = (current-year average index ÷ previous-year average index − 1) × 100. 2017–2022 are compared as complete calendar years. 2023 is shown separately as YTD Jan–May and is not ranked against full years. Missing monthly General Index observations needed for annual averages were linearly interpolated between adjacent observed months.
A10: Excel Formula Used for Annual Average | B10: =AVERAGEIFS('Q2 Monthly Data'!$D:$D,'Q2 Monthly Data'!$A:$A,A13) -> 129.2
